Workbook

Sheet MAIN
A1: Category | B1: Amount | C1: Indicator
A2: Discount Amount | B2: 0.05 | C2: =1 -(B4 + B5 + B7)/(R_OP!B10 + B6) -> 0.16172
A3: Non Operational Expenses | B3: =(R_OP!B10)*(1-B2) -> 475000 | C3: =IF((B3 + B6 ) > (B4 + B5 + B7 ),"🟢","🔴") -> 🟢
A4: Cost Of Goods Sold | B4: =C_COGS!C9 -> 402850 | C4: =IF((B3 + B6 ) > (B4 + B5 + B7 ),"🟢","🔴") -> 🟢
A5: Operational Expenses | B5: =C_OPEX!C13 -> 16290 | C5: =IF((B3 + B6 ) > (B4 + B5 + B7 ),"🟢","🔴") -> 🟢
A6: Non Operational Revenue | B6: =R_NONOP!B7 -> 0 | C6: 🔘
A7: Non Operational Expenses | B7: =C_NONOP!B7 -> 0 | C7: =IF((B3 + B6 ) > (B4 + B5 + B7 ),"🟢","🔴") -> 🟢
A8: Gross Profit | B8: =B3 - B4 -> 72150 | C8: =IF((B3 + B6 ) > (B4 + B5 + B7 ),"🟢","🔴") -> 🟢
A9: Earning Before Interest and Taxes | B9: =B8 -B5 -> 55860 | C9: =IF((B3 + B6 ) > (B4 + B5 + B7 ),"🟢","🔴") -> 🟢
A10: Earning Before Tax | B10: =B9 + B6 -> 55860 | C10: =IF((B3 + B6 ) > (B4 + B5 + B7 ),"🟢","🔴") -> 🟢
A11: Net Profit | B11: =0.78*(B10) -> 43570.8 | C11: =IF((B3 + B6 ) > (B4 + B5 + B7 ),"🟢","🔴") -> 🟢 | D11: p.s. ATM no deductions, only flat rate
A12: Gross Profit Margin | B12: =B8/B3 -> 0.15189474 | C12: =IF((B3 + B6 ) > (B4 + B5 + B7 ),"🟢","🔴") -> 🟢
A13: Operational Profit Margin | B13: =B9/B3 -> 0.1176 | C13: =IF((B3 + B6 ) > (B4 + B5 + B7 ),"🟢","🔴") -> 🟢
A14: Net Profit Margin | B14: =B11/B3 -> 0.091728 | C14: =IF((B3 + B6 ) > (B4 + B5 + B7 ),"🟢","🔴") -> 🟢

Sheet R_OP
A1: Label | B1: Amount
A2: Product Sales Revenue | B2: 500000
A3: Services Revenue | B3: 0
A4: Contract Revenue | B4: 0
A5: Rental & Leasing Revenue | B5: 0
A6: Subscription Revenue | B6: 0
A7: Commission Revenue | B7: 0
A8: Commission & Brokerage Revenue | B8: 0
A9: Licensing & Royalty Revenue | B9: 0
A10: TOTAL | B10: =SUM(B2:B9) -> 500000

Sheet C_COGS
A1: Label | B1: Category | C1: Amount
A2: Direct Materials | B2: Production | C2: =SUM(B26:B29) -> 42000
A3: Merchandise Purchase Cost | B3: Production | C3: =SUM(B14:B23) -> 270000
A4: Direct Production Labor | B4: Labor | C4: =SUM(B32:B40) -> 49000
A5: Direct Service Labor | B5: Labor | C5: 0
A6: Manufacturing Costs | B6: Production | C6: =SUM(B43:B45) -> 3850
A7: Transportation | B7: Logistics | C7: =SUM(B48:B52) -> 37000
A8: Non-Recoverable Acquisition Taxes | B8: Logistics | C8: =SUM(B55) -> 1000
A9: TOTAL | C9: =SUM(C2:C8) -> 402850
G12: p.s. based on main gross margin/which is dependent on chosen Operational Revenue
A13: Merchandise Example | B13: Amount | C13: Quantity Example | D13: Unit | E13: Unit Cost | F13: Unit Price | G13: p.s. uniform markup allocation (same gross margin for each product)
A14: Built-in Furniture | B14: 92500 | C14: 25 | D14: pcs | E14: =B14/C14 -> 3700 | F14: =E14*(1 + MAIN!B12) -> 4262.0105
A15: Freestanding Furniture | B15: 48750 | C15: 75 | D15: pcs | E15: =B15/C15 -> 650 | F15: =E15*(1 + MAIN!B13) -> 726.44
A16: Lighting | B16: 21750 | C16: 50 | D16: pcs | E16: =B16/C16 -> 435 | F16: =E16*(1 + MAIN!B14) -> 474.90168
A17: Sanitary Equipment | B17: 18500 | C17: 25 | D17: pcs | E17: =B17/C17 -> 740 | F17: =E17*(1 + MAIN!B15) -> 740
A18: Parquet & Flooring | B18: 24500 | C18: 350 | D18: m² | E18: =B18/C18 -> 70 | F18: =E18*(1 + MAIN!B16) -> 70
A19: Mirrors | B19: 9500 | C19: 25 | D19: pcs | E19: =B19/C19 -> 380 | F19: =E19*(1 + MAIN!B17) -> 380
A20: Doors | B20: 18750 | C20: 25 | D20: pcs | E20: =B20/C20 -> 750 | F20: =E20*(1 + MAIN!B18) -> 750
A21: Textiles | B21: 10250 | C21: 50 | D21: pcs | E21: =B21/C21 -> 205 | F21: =E21*(1 + MAIN!B19) -> 205
A22: Outdoor Equipment | B22: 12000 | C22: 20 | D22: pcs | E22: =B22/C22 -> 600 | F22: =E22*(1 + MAIN!B20) -> 600
A23: Smart Solutions | B23: 13500 | C23: 15 | D23: sets | E23: =B23/C23 -> 900 | F23: =E23*(1 + MAIN!B21) -> 900
A25: Direct Materials Example | B25: Amount
A26: Stone | B26: 17500 | C26: 125 | D26: m² | E26: =B26/C26 -> 140 | F26: =E26*(1 + MAIN!B24) -> 140
A27: Glass | B27: 5250 | C27: 75 | D27: m² | E27: =B27/C27 -> 70 | F27: =E27*(1 + MAIN!B25) -> 70
A28: Metal | B28: 11950 | C28: 850 | D28: kg | E28: =B28/C28 -> 14.058824 | F28: =E28*(1 + MAIN!B26) -> 14.058824
A29: Wood | B29: 7300 | C29: 180 | D29: m² | E29: =B29/C29 -> 40.555556 | F29: =E29*(1 + MAIN!B27) -> 40.555556
A31: Direct Production Labor Example | B31: Amount
A32: Furniture Installer | B32: 2500
A33: Carpenter | B33: 6750
A34: Stone Installer | B34: 8500
A35: Electrician | B35: 7250
A36: Plumber | B36: 5500
A37: Flooring Installer | B37: 5250
A38: Door Installer | B38: 3750
A39: Metalworker / Metal Installer | B39: 4500
A40: Glass Installer | B40: 5000
A42: Manufacturing Costs Example | B42: Amount
A43: Factory Rent | B43: 3000
A44: Factory Insurance | B44: 750
A45: Quality Control | B45: 100
...

Sheet C_OPEX
A1: Label | B1: Category | C1: Amount
A2: Employee Salaries | B2: Personnel | C2: =SUM(B18:B22) -> 9650
A3: Research & Development | B3: Personnel | C3: 0
A4: Advertising & Marketing Expenses | B4: Services | C4: 0
A5: Accounting & Bookkeeping Fees | B5: Services | C5: =SUM(B25) -> 200
A6: Legal & Attorney Fees | B6: Services | C6: 0
A7: Licensing & Permit Fees | B7: Services | C7: =SUM(B28:B32) -> 1040
A8: Office Rent | B8: Facilities | C8: 1200
A9: Office Expenses | B9: Utilities | C9: =SUM(B35:B39) -> 700
A10: Insurance Expenses | B10: Utilities | C10: =SUM(B42:B44) -> 1100
A11: Travel Expenses | B11: Transportation | C11: =SUM(B46:B47) -> 2400
A12: Vehicle Expenses | B12: Transportation | C12: 0
A13: TOTAL | C13: =SUM(C2:C12) -> 16290
A16: p.s. ; no per project allocation (amortization)
A17: Employee Salaries Example | B17: Amount
A18: Person A | B18: 1450
A19: Person B | B19: 1600
A20: Person C | B20: 1900
A21: Person D | B21: 2200
A22: Person E | B22: 2500
A24: Accounting & Bookkeeping Fees Example | B24: Amount
A25: Accounting Fee | B25: 200
A27: Licensing & Permit Fees Example | B27: Amount
A28: Microsoft 365 License | B28: 150
A29: Microsoft Windows License | B29: 100
A30: Autodesk AutoCAD License | B30: 400
A31: Autodesk Revit License | B31: 300
A32: Adobe License | B32: 90
A34: Office Expenses Example | B34: Amount
A35: Office Supplies | B35: 250
A36: Printing & Copying | B36: 150
A37: Stationery | B37: 100
A38: Postage & Shipping | B38: 100
A39: Cleaning Supplies | B39: 100
A41: Insurance Expenses Example | B41: Amount
A42: General Liability Insurance | B42: 350
A43: Property Insurance | B43: 750
A45: Travel Expenses Example | B45: Amount
A46: Germany Business Travel | B46: 1350
A47: Italy Business Travel | B47: 1050

Sheet R_NONOP
A1: Label | B1: Amount
A2: Interest Income | B2: 0
A3: Dividend Income | B3: 0
A4: Investment Gain | B4: 0
A5: Gains on Financial Instruments | B5: 0
A6: Foreign Exchange Gains | B6: 0
A7: Gains on Disposal of Non-Operating Assets | B7: 0
A8: TOTAL | B8: =SUM(B2:B7) -> 0

Sheet C_NONOP
A1: Label | B1: Amount
A2: Debt Interest | B2: 0
A3: Investment Losses | B3: 0
A4: Losses on Financial Instruments | B4: 0
A5: Foreign Exchange Losses | B5: 0
A6: Losses on Disposal of Non-Operating Assets | B6: 0
A7: TOTAL | B7: =SUM(B2:B6) -> 0

Sheet C_TAX
A1: TODO
